Traceback (most recent call last):
  File "/Users/aaron/miniforge3/envs/eeg/lib/python3.9/site-packages/jupyter_cache/executors/utils.py", line 51, in single_nb_execution
    executenb(
  File "/Users/aaron/miniforge3/envs/eeg/lib/python3.9/site-packages/nbclient/client.py", line 1112, in execute
    return NotebookClient(nb=nb, resources=resources, km=km, **kwargs).execute()
  File "/Users/aaron/miniforge3/envs/eeg/lib/python3.9/site-packages/nbclient/util.py", line 74, in wrapped
    return just_run(coro(*args, **kwargs))
  File "/Users/aaron/miniforge3/envs/eeg/lib/python3.9/site-packages/nbclient/util.py", line 53, in just_run
    return loop.run_until_complete(coro)
  File "/Users/aaron/miniforge3/envs/eeg/lib/python3.9/asyncio/base_events.py", line 642, in run_until_complete
    return future.result()
  File "/Users/aaron/miniforge3/envs/eeg/lib/python3.9/site-packages/nbclient/client.py", line 553, in async_execute
    await self.async_execute_cell(
  File "/Users/aaron/miniforge3/envs/eeg/lib/python3.9/site-packages/nbclient/client.py", line 857, in async_execute_cell
    self._check_raise_for_error(cell, exec_reply)
  File "/Users/aaron/miniforge3/envs/eeg/lib/python3.9/site-packages/nbclient/client.py", line 760, in _check_raise_for_error
    raise CellExecutionError.from_cell_and_msg(cell, exec_reply_content)
nbclient.exceptions.CellExecutionError: An error occurred while executing the following cell:
------------------
life_exp_1900 = 48.1
  life_exp_1920 = 56.6
------------------

[0;36m  File [0;32m"/var/folders/x0/pvpjfdzd39sc5rqvsk5lvv4m0000gn/T/ipykernel_20132/3987155662.py"[0;36m, line [0;32m2[0m
[0;31m    life_exp_1920 = 56.6[0m
[0m    ^[0m
[0;31mIndentationError[0m[0;31m:[0m unexpected indent

IndentationError: unexpected indent (3987155662.py, line 2)

