Traceback (most recent call last):
  File "/Users/aaron/miniforge3/envs/eeg/lib/python3.9/site-packages/jupyter_cache/executors/utils.py", line 51, in single_nb_execution
    executenb(
  File "/Users/aaron/miniforge3/envs/eeg/lib/python3.9/site-packages/nbclient/client.py", line 1112, in execute
    return NotebookClient(nb=nb, resources=resources, km=km, **kwargs).execute()
  File "/Users/aaron/miniforge3/envs/eeg/lib/python3.9/site-packages/nbclient/util.py", line 74, in wrapped
    return just_run(coro(*args, **kwargs))
  File "/Users/aaron/miniforge3/envs/eeg/lib/python3.9/site-packages/nbclient/util.py", line 53, in just_run
    return loop.run_until_complete(coro)
  File "/Users/aaron/miniforge3/envs/eeg/lib/python3.9/asyncio/base_events.py", line 642, in run_until_complete
    return future.result()
  File "/Users/aaron/miniforge3/envs/eeg/lib/python3.9/site-packages/nbclient/client.py", line 553, in async_execute
    await self.async_execute_cell(
  File "/Users/aaron/miniforge3/envs/eeg/lib/python3.9/site-packages/nbclient/client.py", line 857, in async_execute_cell
    self._check_raise_for_error(cell, exec_reply)
  File "/Users/aaron/miniforge3/envs/eeg/lib/python3.9/site-packages/nbclient/client.py", line 760, in _check_raise_for_error
    raise CellExecutionError.from_cell_and_msg(cell, exec_reply_content)
nbclient.exceptions.CellExecutionError: An error occurred while executing the following cell:
------------------
pd.merge(sess_12, sess_3)
------------------

[0;31m---------------------------------------------------------------------------[0m
[0;31mMergeError[0m                                Traceback (most recent call last)
[0;32m/var/folders/x0/pvpjfdzd39sc5rqvsk5lvv4m0000gn/T/ipykernel_20095/92041385.py[0m in [0;36m<module>[0;34m[0m
[0;32m----> 1[0;31m [0mpd[0m[0;34m.[0m[0mmerge[0m[0;34m([0m[0msess_12[0m[0;34m,[0m [0msess_3[0m[0;34m)[0m[0;34m[0m[0;34m[0m[0m
[0m
[0;32m~/miniforge3/envs/eeg/lib/python3.9/site-packages/pandas/core/reshape/merge.py[0m in [0;36mmerge[0;34m(left, right, how, on, left_on, right_on, left_index, right_index, sort, suffixes, copy, indicator, validate)[0m
[1;32m    105[0m     [0mvalidate[0m[0;34m:[0m [0mstr[0m [0;34m|[0m [0;32mNone[0m [0;34m=[0m [0;32mNone[0m[0;34m,[0m[0;34m[0m[0;34m[0m[0m
[1;32m    106[0m ) -> DataFrame:
[0;32m--> 107[0;31m     op = _MergeOperation(
[0m[1;32m    108[0m         [0mleft[0m[0;34m,[0m[0;34m[0m[0;34m[0m[0m
[1;32m    109[0m         [0mright[0m[0;34m,[0m[0;34m[0m[0;34m[0m[0m

[0;32m~/miniforge3/envs/eeg/lib/python3.9/site-packages/pandas/core/reshape/merge.py[0m in [0;36m__init__[0;34m(self, left, right, how, on, left_on, right_on, axis, left_index, right_index, sort, suffixes, copy, indicator, validate)[0m
[1;32m    680[0m             [0mwarnings[0m[0;34m.[0m[0mwarn[0m[0;34m([0m[0mmsg[0m[0;34m,[0m [0mFutureWarning[0m[0;34m,[0m [0mstacklevel[0m[0;34m=[0m[0;36m3[0m[0;34m)[0m[0;34m[0m[0;34m[0m[0m
[1;32m    681[0m [0;34m[0m[0m
[0;32m--> 682[0;31m         [0mself[0m[0;34m.[0m[0m_validate_specification[0m[0;34m([0m[0;34m)[0m[0;34m[0m[0;34m[0m[0m
[0m[1;32m    683[0m [0;34m[0m[0m
[1;32m    684[0m         [0mcross_col[0m [0;34m=[0m [0;32mNone[0m[0;34m[0m[0;34m[0m[0m

[0;32m~/miniforge3/envs/eeg/lib/python3.9/site-packages/pandas/core/reshape/merge.py[0m in [0;36m_validate_specification[0;34m(self)[0m
[1;32m   1340[0m                 [0mcommon_cols[0m [0;34m=[0m [0mleft_cols[0m[0;34m.[0m[0mintersection[0m[0;34m([0m[0mright_cols[0m[0;34m)[0m[0;34m[0m[0;34m[0m[0m
[1;32m   1341[0m                 [0;32mif[0m [0mlen[0m[0;34m([0m[0mcommon_cols[0m[0;34m)[0m [0;34m==[0m [0;36m0[0m[0;34m:[0m[0;34m[0m[0;34m[0m[0m
[0;32m-> 1342[0;31m                     raise MergeError(
[0m[1;32m   1343[0m                         [0;34m"No common columns to perform merge on. "[0m[0;34m[0m[0;34m[0m[0m
[1;32m   1344[0m                         [0;34mf"Merge options: left_on={self.left_on}, "[0m[0;34m[0m[0;34m[0m[0m

[0;31mMergeError[0m: No common columns to perform merge on. Merge options: left_on=None, right_on=None, left_index=False, right_index=False
MergeError: No common columns to perform merge on. Merge options: left_on=None, right_on=None, left_index=False, right_index=False

