Traceback (most recent call last):
  File "/Users/aaron/miniforge3/envs/eeg/lib/python3.9/site-packages/jupyter_cache/executors/utils.py", line 51, in single_nb_execution
    executenb(
  File "/Users/aaron/miniforge3/envs/eeg/lib/python3.9/site-packages/nbclient/client.py", line 1112, in execute
    return NotebookClient(nb=nb, resources=resources, km=km, **kwargs).execute()
  File "/Users/aaron/miniforge3/envs/eeg/lib/python3.9/site-packages/nbclient/util.py", line 74, in wrapped
    return just_run(coro(*args, **kwargs))
  File "/Users/aaron/miniforge3/envs/eeg/lib/python3.9/site-packages/nbclient/util.py", line 53, in just_run
    return loop.run_until_complete(coro)
  File "/Users/aaron/miniforge3/envs/eeg/lib/python3.9/asyncio/base_events.py", line 642, in run_until_complete
    return future.result()
  File "/Users/aaron/miniforge3/envs/eeg/lib/python3.9/site-packages/nbclient/client.py", line 553, in async_execute
    await self.async_execute_cell(
  File "/Users/aaron/miniforge3/envs/eeg/lib/python3.9/site-packages/nbclient/client.py", line 857, in async_execute_cell
    self._check_raise_for_error(cell, exec_reply)
  File "/Users/aaron/miniforge3/envs/eeg/lib/python3.9/site-packages/nbclient/client.py", line 760, in _check_raise_for_error
    raise CellExecutionError.from_cell_and_msg(cell, exec_reply_content)
nbclient.exceptions.CellExecutionError: An error occurred while executing the following cell:
------------------
df = df.set_index('Participant')
df.sample(8)
------------------

[0;31m---------------------------------------------------------------------------[0m
[0;31mKeyError[0m                                  Traceback (most recent call last)
[0;32m/var/folders/x0/pvpjfdzd39sc5rqvsk5lvv4m0000gn/T/ipykernel_14155/1103990505.py[0m in [0;36m<module>[0;34m[0m
[0;32m----> 1[0;31m [0mdf[0m [0;34m=[0m [0mdf[0m[0;34m.[0m[0mset_index[0m[0;34m([0m[0;34m'Participant'[0m[0;34m)[0m[0;34m[0m[0;34m[0m[0m
[0m[1;32m      2[0m [0mdf[0m[0;34m.[0m[0msample[0m[0;34m([0m[0;36m8[0m[0;34m)[0m[0;34m[0m[0;34m[0m[0m

[0;32m~/miniforge3/envs/eeg/lib/python3.9/site-packages/pandas/util/_decorators.py[0m in [0;36mwrapper[0;34m(*args, **kwargs)[0m
[1;32m    309[0m                     [0mstacklevel[0m[0;34m=[0m[0mstacklevel[0m[0;34m,[0m[0;34m[0m[0;34m[0m[0m
[1;32m    310[0m                 )
[0;32m--> 311[0;31m             [0;32mreturn[0m [0mfunc[0m[0;34m([0m[0;34m*[0m[0margs[0m[0;34m,[0m [0;34m**[0m[0mkwargs[0m[0;34m)[0m[0;34m[0m[0;34m[0m[0m
[0m[1;32m    312[0m [0;34m[0m[0m
[1;32m    313[0m         [0;32mreturn[0m [0mwrapper[0m[0;34m[0m[0;34m[0m[0m

[0;32m~/miniforge3/envs/eeg/lib/python3.9/site-packages/pandas/core/frame.py[0m in [0;36mset_index[0;34m(self, keys, drop, append, inplace, verify_integrity)[0m
[1;32m   5444[0m [0;34m[0m[0m
[1;32m   5445[0m         [0;32mif[0m [0mmissing[0m[0;34m:[0m[0;34m[0m[0;34m[0m[0m
[0;32m-> 5446[0;31m             [0;32mraise[0m [0mKeyError[0m[0;34m([0m[0;34mf"None of {missing} are in the columns"[0m[0;34m)[0m[0;34m[0m[0;34m[0m[0m
[0m[1;32m   5447[0m [0;34m[0m[0m
[1;32m   5448[0m         [0;32mif[0m [0minplace[0m[0;34m:[0m[0;34m[0m[0;34m[0m[0m

[0;31mKeyError[0m: "None of ['Participant'] are in the columns"
KeyError: "None of ['Participant'] are in the columns"

