Traceback (most recent call last):
  File "/Users/aaron/miniforge3/envs/eeg/lib/python3.9/site-packages/jupyter_cache/executors/utils.py", line 51, in single_nb_execution
    executenb(
  File "/Users/aaron/miniforge3/envs/eeg/lib/python3.9/site-packages/nbclient/client.py", line 1112, in execute
    return NotebookClient(nb=nb, resources=resources, km=km, **kwargs).execute()
  File "/Users/aaron/miniforge3/envs/eeg/lib/python3.9/site-packages/nbclient/util.py", line 74, in wrapped
    return just_run(coro(*args, **kwargs))
  File "/Users/aaron/miniforge3/envs/eeg/lib/python3.9/site-packages/nbclient/util.py", line 53, in just_run
    return loop.run_until_complete(coro)
  File "/Users/aaron/miniforge3/envs/eeg/lib/python3.9/asyncio/base_events.py", line 642, in run_until_complete
    return future.result()
  File "/Users/aaron/miniforge3/envs/eeg/lib/python3.9/site-packages/nbclient/client.py", line 553, in async_execute
    await self.async_execute_cell(
  File "/Users/aaron/miniforge3/envs/eeg/lib/python3.9/site-packages/nbclient/client.py", line 857, in async_execute_cell
    self._check_raise_for_error(cell, exec_reply)
  File "/Users/aaron/miniforge3/envs/eeg/lib/python3.9/site-packages/nbclient/client.py", line 760, in _check_raise_for_error
    raise CellExecutionError.from_cell_and_msg(cell, exec_reply_content)
nbclient.exceptions.CellExecutionError: An error occurred while executing the following cell:
------------------
###BEGIN SOLUTION
data_europe = pd.read_csv('data/gapminder_gdp_europe.csv', index_col='country')
data_europe.min().plot(label='min')
data_europe.max().plot(label='max')
plt.legend(loc='best')
plt.xticks(rotation=90)
plt.show()
###END SOLUTION
------------------

[0;31m---------------------------------------------------------------------------[0m
[0;31mNameError[0m                                 Traceback (most recent call last)
[0;32m/var/folders/x0/pvpjfdzd39sc5rqvsk5lvv4m0000gn/T/ipykernel_49121/2215409995.py[0m in [0;36m<module>[0;34m[0m
[1;32m      1[0m [0;31m###BEGIN SOLUTION[0m[0;34m[0m[0;34m[0m[0;34m[0m[0m
[0;32m----> 2[0;31m [0mdata_europe[0m [0;34m=[0m [0mpd[0m[0;34m.[0m[0mread_csv[0m[0;34m([0m[0;34m'data/gapminder_gdp_europe.csv'[0m[0;34m,[0m [0mindex_col[0m[0;34m=[0m[0;34m'country'[0m[0;34m)[0m[0;34m[0m[0;34m[0m[0m
[0m[1;32m      3[0m [0mdata_europe[0m[0;34m.[0m[0mmin[0m[0;34m([0m[0;34m)[0m[0;34m.[0m[0mplot[0m[0;34m([0m[0mlabel[0m[0;34m=[0m[0;34m'min'[0m[0;34m)[0m[0;34m[0m[0;34m[0m[0m
[1;32m      4[0m [0mdata_europe[0m[0;34m.[0m[0mmax[0m[0;34m([0m[0;34m)[0m[0;34m.[0m[0mplot[0m[0;34m([0m[0mlabel[0m[0;34m=[0m[0;34m'max'[0m[0;34m)[0m[0;34m[0m[0;34m[0m[0m
[1;32m      5[0m [0mplt[0m[0;34m.[0m[0mlegend[0m[0;34m([0m[0mloc[0m[0;34m=[0m[0;34m'best'[0m[0;34m)[0m[0;34m[0m[0;34m[0m[0m

[0;31mNameError[0m: name 'pd' is not defined
NameError: name 'pd' is not defined

